Workbook

Sheet Portada
B2: MODELO DE CIUDAD INTELIGENTE
B5: Cúcuta – Norte de Santander, Colombia
B9: Dimensión | C9: N° Indicadores | D9: Peso (%) | E9: Fuente Principal
B10: Capital Humano | C10: 13 | D10: 16 | E10: Euromonitor / OpenStreetMap / UNESCO
B11: Cohesión Social | C11: 13 | D11: 16 | E11: Numbeo / Euromonitor / Walk Free Foundation
B12: Economía | C12: 6 | D12: 16 | E12: World Bank / Euromonitor / Fortune 500
B13: Gobernanza | C13: 7 | D13: 16 | E13: United Nations / World Bank / WCCD
B14: Medio Ambiente | C14: 11 | D14: 16 | E14: World Bank / Yale / IQAir / FAO
B15: Frontera | C15: 10 | D15: 20 | E15: DANE / DIAN / Migración Colombia / BCV
B16: TOTAL | C16: =SUM(C10:C15) -> 60 | D16: =SUM(D10:D15) -> 100
B19: Instrucciones de uso
B20: 1. Cada hoja contiene los indicadores de una dimensión con su descripción, fuente y columna de puntuación (0-10).
B21: 2. Ingrese los valores reales de Cúcuta en la columna 'Valor Real'. El puntaje se calcula automáticamente.
B22: 3. La hoja 'Resumen Puntajes' consolida el índice compuesto final.
B23: 4. Los pesos por dimensión pueden ajustarse en la columna 'Peso' del Resumen.

Sheet Capital Humano
A1: INDICADORES DE CAPITAL HUMANO
A2: No. | B2: Indicador | C2: Descripción / Unidad de medida | D2: Tipo | E2: Valor Real | F2: Ref. Óptima | G2: Puntaje (0-10) | H2: Justificación del indicador | I2: Link de fuente | J2: Año del dato
A3: 1 | B3: Cobertura neta Educación Básica Secundaria | C3: Porcentaje (%) — Estudiantes en edad de cursar grados 6° a 9° efectivamente matriculados. | D3: Positivo ↑ | E3: 84.3 | F3: 95 | G3: =IF(E3="","–",IF(D3="Negativo ↓",MIN(10,MAX(0,IFERROR(F3/E3*10,0))),MIN(10,MAX(0,IFERROR(E3/F3*10,0))))) -> 8.8736842 | H3: Mide el acceso a educación secundaria básica. Una Smart City requiere capital humano formado; ciudades con baja cobertura en este nivel tienen mayor informalidad y menor adopción tecnológica. | I3: https://fundacionexe.org.co/wp-content/uploads/2024/03/%C2%BFComo-esta-Cucuta-en-educacion-Retos-y-prioridades-2024-2027.pdf | J3: 2022
A4: 2 | B4: Cobertura neta Educación Media | C4: Porcentaje (%) — Estudiantes en edad de cursar grados 10° y 11° efectivamente matriculados. | D4: Positivo ↑ | E4: 54.7 | F4: 80 | G4: =IF(E4="","–",IF(D4="Negativo ↓",MIN(10,MAX(0,IFERROR(F4/E4*10,0))),MIN(10,MAX(0,IFERROR(E4/F4*10,0))))) -> 6.8375 | H4: Cuantifica el abandono escolar antes del bachillerato. La brecha entre secundaria y media revela el principal cuello de botella del capital humano en ciudades fronterizas como Cúcuta. | I4: https://fundacionexe.org.co/wp-content/uploads/2024/03/%C2%BFComo-esta-Cucuta-en-educacion-Retos-y-prioridades-2024-2027.pdf | J4: 2022
A5: 3 | B5: Cobertura Educación Superior | C5: Porcentaje (%) — Tasa de cobertura en educación superior (técnica, tecnológica o universitaria). | D5: Positivo ↑ | E5: 53.94 | F5: 70 | G5: =IF(E5="","–",IF(D5="Negativo ↓",MIN(10,MAX(0,IFERROR(F5/E5*10,0))),MIN(10,MAX(0,IFERROR(E5/F5*10,0))))) -> 7.7057143 | H5: Indica qué proporción de jóvenes accede a formación superior. Sin educación universitaria no hay innovación local ni mercado laboral calificado para sostener una economía digital. | I5: https://fundacionexe.org.co/wp-content/uploads/2024/03/¿Como-esta-Cucuta-en-educacion-Retos-y-prioridades-2024-2027.pdf | J5: 2022
A6: 4 | B6: Conectividad escolar (% sedes con internet activo) | C6: Porcentaje (%) — Sedes educativas oficiales con conexión a internet activa. | D6: Positivo ↑ | E6: 85.3 | F6: 100 | G6: =IF(E6="","–",IF(D6="Negativo ↓",MIN(10,MAX(0,IFERROR(F6/E6*10,0))),MIN(10,MAX(0,IFERROR(E6/F6*10,0))))) -> 8.53 | H6: Mide la digitalización del sistema educativo. Una ciudad inteligente necesita que sus escuelas estén conectadas para formar ciudadanos digitales desde edad temprana. | I6: https://fundacionexe.org.co/wp-content/uploads/2024/03/%C2%BFComo-esta-Cucuta-en-educacion-Retos-y-prioridades-2024-2027.pdf | J6: 2022
A7: 5 | B7: Tasa de analfabetismo (%) | C7: Porcentaje (%) — Población de 15 años y más que no sabe leer ni escribir. NEGATIVO: menor valor = mejor. | D7: Negativo ↓ | E7: 3.4 | F7: 2 | G7: =IF(E7="","–",IF(D7="Negativo ↓",MIN(10,MAX(0,IFERROR(F7/E7*10,0))),MIN(10,MAX(0,IFERROR(E7/F7*10,0))))) -> 5.8823529 | H7: El analfabetismo limita directamente la adopción de servicios digitales y la participación ciudadana. Reducirlo es condición base para cualquier estrategia Smart City inclusiva. | I7: https://cucutacomovamos.com/wp-content/uploads/2022/02/informe-2019.pdf | J7: 2018
A8: 6 | B8: Participación en actividad física (% población) | C8: Porcentaje (%) — Población que participa en programas de actividad física, deporte o recreación. | D8: Positivo ↑ | E8: 13.4 | F8: 40 | G8: =IF(E8="","–",IF(D8="Negativo ↓",MIN(10,MAX(0,IFERROR(F8/E8*10,0))),MIN(10,MAX(0,IFERROR(E8/F8*10,0))))) -> 3.35 | H8: El sedentarismo genera altos costos en salud pública. Una Smart City promueve el bienestar físico a través de infraestructura deportiva y programas que reducen la carga del sistema sanitario. | I8: https://administrador.nortedesantander.gov.co/wp-content/uploads/2023/11/BALANCE-DE-GESTION-2020-2023-INDENORTE.pdf | J8: 2023
A9: 7 | B9: Tasa de mortalidad infantil (por 1.000 nv) | C9: Número de muertes de menores de 1 año por cada 1.000 nacidos vivos. NEGATIVO: menor valor = mejor. (Dato nacional Colombia — DANE no publica desagregación a nivel ciudad para todos los años) | D9: Negativo ↓ | E9: 15 | F9: 8 | G9: =IF(E9="","–",IF(D9="Negativo ↓",MIN(10,MAX(0,IFERROR(F9/E9*10,0))),MIN(10,MAX(0,IFERROR(E9/F9*10,0))))) -> 5.3333333 | H9: La mortalidad infantil refleja la calidad del sistema de salud y las condiciones socioeconómicas. Una ciudad inteligente garantiza que ningún niño muera por causas prevenibles. | I9: https://cucuta.gov.co/wp-content/uploads/2023/12/Indicadores-de-resultados.pdf | J9: 2022
A10: 8 | B10: Colegios con salas STEM o laboratorios TIC (%) | C10: Porcentaje (%) — Instituciones educativas con salas dotadas de computadores, robótica o labs TIC. | D10: Positivo ↑ | E10: 62.5 | F10: 50 | G10: =IF(E10="","–",IF(D10="Negativo ↓",MIN(10,MAX(0,IFERROR(F10/E10*10,0))),MIN(10,MAX(0,IFERROR(E10/F10*10,0))))) -> 10 | H10: Las salas STEM y laboratorios TIC son la infraestructura de innovación del futuro. Sin ellas, la ciudad no puede formar el talento digital que demanda una economía del conocimiento. | I10: https://fundacionexe.org.co/wp-content/uploads/2024/03/%C2%BFComo-esta-Cucuta-en-educacion-Retos-y-prioridades-2024-2027.pdf | J10: 2022
A11: 9 | B11: Penetración internet fijo en hogares (%) | C11: Porcentaje (%) — Hogares con acceso a internet de banda ancha fija. | D11: Positivo ↑ | E11: 45 | F11: 65 | G11: =IF(E11="","–",IF(D11="Negativo ↓",MIN(10,MAX(0,IFERROR(F11/E11*10,0))),MIN(10,MAX(0,IFERROR(E11/F11*10,0))))) -> 6.9230769 | H11: El internet fijo es la infraestructura base de la economía digital. Sin conectividad en el hogar, los ciudadanos quedan excluidos del trabajo remoto, el comercio electrónico y los servicios digitales. | I11: https://mintic.gov.co/portal/inicio/Sala-de-prensa/MinTIC-en-los-medios/176311:Gobierno-y-operadores-privados-buscan-mejorar-conectividad-en-Norte-de-Santander | J11: 2021
A12: 10 | B12: Programas universitarios en TIC activos | C12: Número entero — Carreras vigentes en sistemas, software, telecomunicaciones o afines en IES de Cúcuta. | D12: Positivo ↑ | E12: 9 | F12: 20 | G12: =IF(E12="","–",IF(D12="Negativo ↓",MIN(10,MAX(0,IFERROR(F12/E12*10,0))),MIN(10,MAX(0,IFERROR(E12/F12*10,0))))) -> 4.5 | H12: Los programas TIC universitarios determinan cuántos ingenieros y desarrolladores locales puede producir la ciudad. Sin este talento, Cúcuta depende de importar conocimiento externo. | I12: https://ingsistemas.ufps.edu.co | J12: 2024
A13: 11 | B13: Universidades en TOP 500 mundial | C13: Número entero — Universidades en QS World University Rankings TOP 500. (0=ninguna / mayor=mejor) | D13: Positivo ↑ | E13: 0 | F13: 1 | G13: =IF(E13="","–",IF(D13="Negativo ↓",MIN(10,MAX(0,IFERROR(F13/E13*10,0))),MIN(10,MAX(0,IFERROR(E13/F13*10,0))))) -> 0 | H13: La presencia en rankings mundiales atrae inversión, investigación y talento internacional. Es el indicador más visible de la capacidad académica y de innovación de una ciudad. | I13: https://www.topuniversities.com/world-university-rankings/2025 | J13: 2025
A14: 12 | B14: Tasa de alfabetización digital (%) | C14: Porcentaje (%) — Población de 5 años y más que usa internet desde cualquier dispositivo. | D14: Positivo ↑ | E14: 73 | F14: 90 | G14: =IF(E14="","–",IF(D14="Negativo ↓",MIN(10,MAX(0,IFERROR(F14/E14*10,0))),MIN(10,MAX(0,IFERROR(E14/F14*10,0))))) -> 8.1111111 | H14: Mide la inclusión digital real de la población. Sin alfabetización digital, la mayoría de los ciudadanos no puede beneficiarse de los servicios que ofrece una ciudad inteligente. | I14: https://cucuta.gov.co/mas-de-70-cucutenos-fueron-capacitados-en-alfabetizacion-digital/ | J14: 2022
A15: 13 | B15: Índice de Pobreza Multidimensional — IPM (%) | C15: Porcentaje (%) — Población en situación de pobreza multidimensional (educación, salud, trabajo, vivienda y servicios). NEGATIVO: menor valor = mejor. (Dato de Norte de Santander — DANE no publica IPM a nivel ciudad) | D15: Negativo ↓ | E15: 20.5 | F15: 10 | G15: =IF(E15="","–",IF(D15="Negativo ↓",MIN(10,MAX(0,IFERROR(F15/E15*10,0))),MIN(10,MAX(0,IFERROR(E15/F15*10,0))))) -> 4.8780488 | H15: El IPM mide privaciones simultáneas en educación, salud, trabajo y vivienda. Una Smart City genuina reduce la pobreza multidimensional, no solo mejora su infraestructura tecnológica. Es el indicador más completo del bienestar real de la población. | I15: https://www.laopinion.co/economia/crece-el-numero-de-personas-en-pobreza-multidimensional-en-norte-de-santander | J15: 2023
A16: PUNTAJE PROMEDIO DE LA DIMENSIÓN | G16: =IFERROR(AVERAGEIF(G3:G15,"<>–"),0) -> 6.2249863

Sheet Cohesión Social
A1: INDICADORES DE COHESIÓN SOCIAL
A2: No. | B2: Indicador | C2: Descripción / Unidad de medida | D2: Tipo | E2: Valor Real | F2: Ref. Óptima | G2: Puntaje (0-10) | H2: Justificación del indicador | I2: Link de fuente | J2: Año del dato
A3: 1 | B3: Coeficiente de Gini | C3: Escala 0-1 — Mide la desigualdad en la distribución del ingreso. NEGATIVO: (0=perfecta igualdad / 1=máxima desigualdad) | D3: Negativo ↓ | E3: 0.461 | F3: 0.35 | G3: =IF(E3="","–",IF(D3="Negativo ↓",MIN(10,MAX(0,IFERROR(F3/E3*10,0))),MIN(10,MAX(0,IFERROR(E3/F3*10,0))))) -> 7.5921909 | H3: La desigualdad extrema fragmenta el tejido social y crea dos ciudades dentro de una. Una Smart City necesita distribución equitativa del ingreso para que sus beneficios lleguen a todos los ciudadanos, no solo a los más pudientes. | I3: https://www.dane.gov.co/files/operaciones/PM/bol-PM-2024.pdf | J3: 2024
A4: 2 | B4: Tasa de informalidad laboral (%) | C4: Porcentaje (%) — Trabajadores sin contrato formal ni seguridad social. NEGATIVO: menor valor = mejor. | D4: Negativo ↓ | E4: 62.8 | F4: 35 | G4: =IF(E4="","–",IF(D4="Negativo ↓",MIN(10,MAX(0,IFERROR(F4/E4*10,0))),MIN(10,MAX(0,IFERROR(E4/F4*10,0))))) -> 5.5732484 | H4: La informalidad laboral impide la recaudación fiscal, limita la inversión en infraestructura urbana y excluye a los trabajadores de la seguridad social. Una ciudad inteligente formaliza su economía para financiar su propio desarrollo. | I4: https://www.elcolombiano.com/negocios/informalidad-laboral-colombia-55-por-ciento-2026-JH35456708 | J4: 2026
A5: 3 | B5: Tasa de desempleo (%) | C5: Porcentaje (%) — Población económicamente activa que está desocupada. NEGATIVO: menor valor = mejor. | D5: Negativo ↓ | E5: 15.1 | F5: 8 | G5: =IF(E5="","–",IF(D5="Negativo ↓",MIN(10,MAX(0,IFERROR(F5/E5*10,0))),MIN(10,MAX(0,IFERROR(E5/F5*10,0))))) -> 5.2980132 | H5: El desempleo estructural indica que la ciudad no genera suficiente valor económico para absorber su fuerza laboral. Una Smart City atrae inversión, fomenta el emprendimiento digital y reduce la dependencia del sector informal. | I5: https://colaboracion.dnp.gov.co/CDT/Estudios%20Econmicos/6%20Informe%20C%C3%BAcuta%202024%20V.2.pdf | J5: 2024
A6: 4 | B6: Tasa de empleo femenino (%) | C6: Porcentaje (%) — Tasa de ocupación de mujeres en edad laboral. Fórmula: 176.489 mujeres ocupadas / 407.000 mujeres PET × 100 = 43.4%. | D6: Positivo ↑ | E6: 43.4 | F6: 60 | G6: =IF(E6="","–",IF(D6="Negativo ↓",MIN(10,MAX(0,IFERROR(F6/E6*10,0))),MIN(10,MAX(0,IFERROR(E6/F6*10,0))))) -> 7.2333333 | H6: La equidad de género en el mercado laboral es un indicador de justicia social. Las ciudades inteligentes aprovechan el 100% de su capital humano — excluir a las mujeres del trabajo formal es un desperdicio de talento y un freno al desarrollo. | I6: https://cucuta.gov.co/wp-content/uploads/2026/03/Analisis-del-mercado-laboral-femenino-en-Cucuta-y-su-area-metropolitana-1.pdf | J6: 2023
A7: 5 | B7: Tasa de homicidios (por 100k hab) | C7: Número de homicidios por cada 100.000 habitantes. NEGATIVO: menor valor = mejor. Fórmula referencial: 303 homicidios / 1.008.000 hab × 100.000 = 30.06 (valor modelo usa tasa 2023: 33.8) | D7: Negativo ↓ | E7: 33.8 | F7: 10 | G7: =IF(E7="","–",IF(D7="Negativo ↓",MIN(10,MAX(0,IFERROR(F7/E7*10,0))),MIN(10,MAX(0,IFERROR(E7/F7*10,0))))) -> 2.9585799 | H7: La violencia homicida destruye el capital social, ahuyenta la inversión y paraliza la vida urbana. Ninguna ciudad puede ser inteligente si sus ciudadanos no pueden circular con seguridad. Es el indicador más crítico de cohesión social. | I7: https://ligacontraelsilencio.com/2024/08/29/cucuta-vive-bajo-el-terror-de-al-menos-20-grupos-criminales/ | J7: 2023
A8: 6 | B8: Violencia intrafamiliar (por 100k hab) | C8: Casos de violencia doméstica por cada 100.000 habitantes. NEGATIVO: menor valor = mejor. | D8: Negativo ↓ | E8: 210.8 | F8: 80 | G8: =IF(E8="","–",IF(D8="Negativo ↓",MIN(10,MAX(0,IFERROR(F8/E8*10,0))),MIN(10,MAX(0,IFERROR(E8/F8*10,0))))) -> 3.7950664 | H8: La violencia intrafamiliar destruye la unidad básica de la sociedad. Impacta la salud mental, el rendimiento escolar y la productividad laboral. Una ciudad inteligente protege a sus ciudadanos más vulnerables dentro de sus propias casas. | I8: https://cucuta.gov.co/wp-content/uploads/2023/12/Indicadores-de-resultados.pdf | J8: 2022
A9: 7 | B9: Tasa de suicidios (por 100k hab) | C9: Número de muertes por suicidio por cada 100.000 habitantes. NEGATIVO: menor valor = mejor. Fórmula: 51 casos / 1.008.000 hab × 100.000 = 5.06 | D9: Negativo ↓ | E9: 5.06 | F9: 3 | G9: =IF(E9="","–",IF(D9="Negativo ↓",MIN(10,MAX(0,IFERROR(F9/E9*10,0))),MIN(10,MAX(0,IFERROR(E9/F9*10,0))))) -> 5.9288538 | H9: La tasa de suicidios es el termómetro del bienestar mental colectivo. Una Smart City invierte en salud mental y redes de apoyo porque entiende que el capital humano emocionalmente sano es su activo más valioso. | I9: https://www.medicinalegal.gov.co/documents/20143/1124000/Forensis_2023.pdf | J9: 2024
A10: 8 | B10: Tasa de mortalidad general (por 1.000 hab) | C10: Número de defunciones por cada 1.000 habitantes. NEGATIVO: menor valor = mejor. | D10: Negativo ↓ | E10: 9.3 | F10: 6 | G10: =IF(E10="","–",IF(D10="Negativo ↓",MIN(10,MAX(0,IFERROR(F10/E10*10,0))),MIN(10,MAX(0,IFERROR(E10/F10*10,0))))) -> 6.4516129 | H10: La mortalidad general refleja el estado integral de salud pública y condiciones de vida. Una ciudad inteligente reduce su mortalidad mediante prevención, digitalización de la salud y mejora de condiciones urbanas. | I10: https://cucutacomovamos.com/wp-content/uploads/2022/02/INDICADORES-TECNICOS-2021.pdf | J10: 2020
A11: 9 | B11: Tasa de mortalidad infantil (por 1.000 nv) | C11: Muertes de menores de 1 año por cada 1.000 nacidos vivos. NEGATIVO: menor valor = mejor. (Dato nacional Colombia — DANE no publica desagregación a nivel ciudad) | D11: Negativo ↓ | E11: 10.82 | F11: 8 | G11: =IF(E11="","–",IF(D11="Negativo ↓",MIN(10,MAX(0,IFERROR(F11/E11*10,0))),MIN(10,MAX(0,IFERROR(E11/F11*10,0))))) -> 7.3937153 | H11: La mortalidad infantil mide si la ciudad protege a sus ciudadanos más vulnerables desde el primer día de vida. Es el indicador de bienestar social más reconocido internacionalmente (ISO 37122) para evaluar la calidad de vida urbana. | I11: https://www.asivamosensalud.org/indicadores/poblaciones-vulnerables/tasa-de-mortalidad-infantil-georeferenciado | J11: 2023
A12: 10 | B12: IPS públicas habilitadas con estándares de calidad (%) | C12: Porcentaje (%) — IPS de la red pública certificadas con estándares del Sistema Único de Habilitación. Fórmula: 13 IPS certificadas / 37 IPS totales × 100 = 35.1% | D12: Positivo ↑ | E12: 35.1 | F12: 100 | G12: =IF(E12="","–",IF(D12="Negativo ↓",MIN(10,MAX(0,IFERROR(F12/E12*10,0))),MIN(10,MAX(0,IFERROR(E12/F12*10,0))))) -> 3.51 | H12: La calidad certificada del sistema de salud determina si los ciudadanos reciben atención segura. Una Smart City garantiza estándares mínimos en sus instalaciones de salud — sin esto, la tecnología médica no tiene dónde implementarse. | I12: https://www.imsalud.gov.co/web/sala-de-prensa/ultimas-noticias/imsalud-certifica-en-habilitacion-a-13-ips-de-su-red-un-avance-significativo-en-salud-para-cucuta-y-la-region-fronteriza/ | J12: 2024
A13: 11 | B13: Cobertura 4G/5G en área urbana (%) | C13: Porcentaje (%) — Área urbana con cobertura 4G o superior activa (incluye 4G, 4G+ y 5G). Verificable en mapa de cobertura nPerf. | D13: Positivo ↑ | E13: 100 | F13: 100 | G13: =IF(E13="","–",IF(D13="Negativo ↓",MIN(10,MAX(0,IFERROR(F13/E13*10,0))),MIN(10,MAX(0,IFERROR(E13/F13*10,0))))) -> 10 | H13: La cobertura móvil de alta velocidad es la infraestructura base de cualquier Smart City. Sin 4G/5G no hay IoT, no hay gobierno digital móvil, no hay aplicaciones ciudadanas. Cúcuta alcanzó cobertura total urbana y además tiene 5G activo. | I13: https://www.nperf.com/es/map/CO/3685533.Cucuta/7239.Movistar-Movil/signal?ll=7.89415921665735&lg=-72.50392913818361&zoom=13 | J13: 2025
A14: 12 | B14: Pobreza monetaria (%) | C14: Porcentaje (%) — Población que vive con ingresos por debajo de la línea de pobreza monetaria. NEGATIVO: menor valor = mejor. | D14: Negativo ↓ | E14: 37.7 | F14: 20 | G14: =IF(E14="","–",IF(D14="Negativo ↓",MIN(10,MAX(0,IFERROR(F14/E14*10,0))),MIN(10,MAX(0,IFERROR(E14/F14*10,0))))) -> 5.3050398 | H14: La pobreza monetaria determina quién puede beneficiarse de una ciudad inteligente. Si el 37.7% no cubre necesidades básicas, las inversiones en tecnología urbana no les llegan. Reducir la pobreza es la condición más fundamental para una Smart City inclusiva. | I14: https://www.dane.gov.co/files/operaciones/PM/bol-PM-2024.pdf | J14: 2024
A15: 13 | B15: Tasa de desempleo juvenil (%) | C15: Porcentaje (%) — Jóvenes de 14 a 28 años desempleados sobre PEA juvenil. NEGATIVO: menor valor = mejor. | D15: Negativo ↓ | E15: 18.52 | F15: 12 | G15: =IF(E15="","–",IF(D15="Negativo ↓",MIN(10,MAX(0,IFERROR(F15/E15*10,0))),MIN(10,MAX(0,IFERROR(E15/F15*10,0))))) -> 6.4794816 | H15: El desempleo juvenil es el indicador más crítico del futuro de una ciudad. Si sus jóvenes no encuentran trabajo formal, emigran o caen en la informalidad. Una Smart City retiene su talento joven creando ecosistemas de emprendimiento e innovación digital. | I15: anex-GEIHMLJ-dic2025-feb2026.xlsx | J15: 2026
A16: PUNTAJE PROMEDIO DE LA DIMENSIÓN | G16: =IFERROR(AVERAGEIF(G3:G15,"<>–"),0) -> 5.9630104

Sheet Economía
A1: INDICADORES DE ECONOMÍA
A2: No. | B2: Indicador | C2: Descripción / Unidad de medida | D2: Tipo | E2: Valor Real | F2: Ref. Óptima | G2: Puntaje (0-10) | H2: Justificación del indicador para Smart City | I2: Link de fuente | J2: Año del dato
A3: 1 | B3: Valor Agregado municipal/local (millones USD) | C3: Millones de USD — Valor Agregado Bruto (VAB) municipal a precios corrientes. El DANE (Departamento Administrativo Nacional de Estadística) publica el Valor Agregado (equivalente al PIB sin impuestos netos sobre productos) a nivel municipal. Fórmula: $13.064.335 millones COP / TRM (Tasa de Representación del Mercado) promedio 2023 ($4.325) = ~$3.021M USD. Dato: 2023p (preliminar). POSITIVO: mayor valor = mejor. | D3: Positivo ↑ | E3: 3021 | F3: 5000 | G3: =IF(E3="","–",IF(D3="Negativo ↓",MIN(10,MAX(0,IFERROR(F3/E3*10,0))),MIN(10,MAX(0,IFERROR(E3/F3*10,0))))) -> 6.042 | H3: El Valor Agregado municipal es el termómetro económico de la ciudad. Una Smart City necesita una economía sólida y en crecimiento para financiar su transformación digital. Sin base económica no hay inversión en infraestructura inteligente, innovación ni servicios digitales para los ciudadanos. Este indicador permite comparar el peso económico de Cúcuta frente a otras ciudades fronterizas de LATAM (América Latina y el Caribe). | I3: https://www.dane.gov.co/index.php/estadisticas-por-tema/cuentas-nacionales/cuentas-nacionales-departamentales | J3: 2023p
A4: 2 | B4: Tasa de crecimiento económico (%) | C4: Porcentaje (%) — Tasa de crecimiento promedio anual del PIB (Producto Interno Bruto) municipal. Fuente: Alcaldía de Cúcuta — Análisis PIB Municipal (DANE). Promedio del período 2015-2021. POSITIVO: mayor valor = mejor. | D4: Positivo ↑ | E4: 6.3 | F4: 8 | G4: =IF(E4="","–",IF(D4="Negativo ↓",MIN(10,MAX(0,IFERROR(F4/E4*10,0))),MIN(10,MAX(0,IFERROR(E4/F4*10,0))))) -> 7.875 | H4: La tasa de crecimiento económico muestra si la ciudad está avanzando o estancada. Una Smart City combina crecimiento económico con innovación y sostenibilidad. El 6.3% de Cúcuta supera el promedio nacional colombiano (~3%), lo que refleja el dinamismo de la economía fronteriza — especialmente tras la reapertura de la frontera con Venezuela en 2022. | I4: https://cucuta.gov.co/wp-content/uploads/2023/12/PIB-municipal.pdf | J4: 2015-2021
A5: 3 | B5: Ingreso laboral promedio mensual (USD) | C5: USD por mes — ILP (Ingreso Laboral Promedio) mensual de los ocupados en Cúcuta A.M. (Área Metropolitana). Fuente: DNP (Departamento Nacional de Planeación) — Informe Mercado Laboral Urbano IV-2024. Cúcuta tiene el ILP más bajo de las 13 principales áreas metropolitanas de Colombia. Valor calculado: ~$340 USD/mes (~$1.419.000 COP / TRM $4.200). POSITIVO: mayor valor = mejor. | D5: Positivo ↑ | E5: 340 | F5: 600 | G5: =IF(E5="","–",IF(D5="Negativo ↓",MIN(10,MAX(0,IFERROR(F5/E5*10,0))),MIN(10,MAX(0,IFERROR(E5/F5*10,0))))) -> 5.6666667 | H5: El ILP (Ingreso Laboral Promedio) mide la capacidad adquisitiva real de los ciudadanos. Una ciudad inteligente no solo genera empleo — genera empleo de calidad y bien remunerado. El bajo ILP de Cúcuta refleja el impacto de la alta informalidad (62.8%) y la presión migratoria venezolana sobre el mercado laboral. Mejorar este indicador requiere políticas de formalización y desarrollo de sectores de alto valor agregado. | I5: https://colaboracion.dnp.gov.co/CDT/Estudios%20Econmicos/6%20Informe%20C%C3%BAcuta%202024%20IV.pdf | J5: 2024
A6: 4 | B6: Días para crear una empresa | C6: Número de días — Tiempo promedio para constituir legalmente una empresa en Colombia. Fuente: MinCIT (Ministerio de Comercio, Industria y Turismo) / Banco Mundial — Doing Business. Colombia ocupa el puesto 96 entre 190 países con 11 días para abrir empresa. NEGATIVO: menor valor = mejor. | D6: Negativo ↓ | E6: 11 | F6: 3 | G6: =IF(E6="","–",IF(D6="Negativo ↓",MIN(10,MAX(0,IFERROR(F6/E6*10,0))),MIN(10,MAX(0,IFERROR(E6/F6*10,0))))) -> 2.7272727 | H6: El tiempo para crear una empresa mide la agilidad del entorno regulatorio para el emprendimiento. Una Smart City simplifica trámites mediante ventanillas únicas digitales y formularios en línea. 11 días es un avance frente al promedio regional latinoamericano, pero ciudades líderes como Singapur lo hacen en menos de 1 día. Este indicador es directamente comparable entre todas las ciudades del mundo con metodología Banco Mundial. | I6: https://www.mincit.gov.co/servicio-ciudadano/preguntas-frecuentes/mipymes/cual-es-el-tiempo-de-apertura-de-una-empresa-en-co | J6: 2022
A7: 5 | B7: Exportaciones totales (millones USD) | C7: Millones de USD por año — Valor total de exportaciones no minero-energéticas del departamento Norte de Santander. Fuente: MinCIT (Ministerio de Comercio, Industria y Turismo) / DIAN (Dirección de Impuestos y Aduanas Nacionales). Primer semestre 2023: $45M USD × 2 = ~$90M USD anualizados. Nota: dato departamental — Cúcuta concentra la mayoría de las exportaciones de Norte de Santander. POSITIVO: mayor valor = mejor. | D7: Positivo ↑ | E7: 90 | F7: 300 | G7: =IF(E7="","–",IF(D7="Negativo ↓",MIN(10,MAX(0,IFERROR(F7/E7*10,0))),MIN(10,MAX(0,IFERROR(E7/F7*10,0))))) -> 3 | H7: Las exportaciones miden la competitividad real de la economía local en los mercados internacionales. Una Smart City desarrolla plataformas de comercio exterior digital, inteligencia de mercados y zonas económicas especiales para atraer inversión. Cúcuta tiene ventaja geográfica única como ciudad fronteriza con potencial exportador hacia Venezuela, pero depende de la estabilidad política binacional. | I7: https://www.semana.com/mejor-colombia/articulo/norte-de-santander-renaciendo-economicamente-tras-la-reapertura-de-la-frontera-y-la-pandemia/202300/ | J7: 2023
A8: 6 | B8: Empresas nuevas registradas (matrícula anual) | C8: Número de empresas — Total de empresas matriculadas por primera vez en el año ante la CCC (Cámara de Comercio de Cúcuta). Fuente: CCC / Confecámaras — La República. Incluye todos los sectores y tamaños. POSITIVO: mayor valor = mejor. | D8: Positivo ↑ | E8: 8057 | F8: 12000 | G8: =IF(E8="","–",IF(D8="Negativo ↓",MIN(10,MAX(0,IFERROR(F8/E8*10,0))),MIN(10,MAX(0,IFERROR(E8/F8*10,0))))) -> 6.7141667 | H8: Las nuevas matrículas empresariales miden la vitalidad emprendedora del ecosistema local. Una Smart City fomenta el emprendimiento con incubadoras digitales, acceso a financiamiento y trámites 100% en línea. Más de 8.000 nuevas empresas en 2023 es una señal positiva, aunque la alta informalidad sugiere que muchas operan fuera del sistema formal. La formalización progresiva es un eje clave de la agenda Smart City. | I8: https://www.larepublica.co/especiales/las-mas-vendedoras-del-norte-de-santander/se-crearon-mas-de-8-000-empresas-en-el-ultimo-ano-3985803 | J8: 2023
A9: PUNTAJE PROMEDIO DE LA DIMENSIÓN | G9: =IFERROR(AVERAGEIF(G3:G8,"<>–"),0) -> 5.3375177

Sheet Gobernanza
A1: INDICADORES DE GOBERNANZA
A2: No. | B2: Indicador | C2: Descripción / Unidad de medida | D2: Tipo | E2: Valor Real | F2: Ref. Óptima | G2: Puntaje (0-10) | H2: Justificación del indicador para Smart City | I2: Link de fuente | J2: Año del dato
A3: 1 | B3: Índice de Madurez de Ciudad Inteligente (escala 0-5 normalizada) | C3: Escala 0-5 — Modelo de Madurez de Ciudades y Territorios Inteligentes del MinTIC. Evalúa calidad de vida, hábitat, medio ambiente, economía, gobernanza y personas. (0=sin madurez / 5=máxima madurez) | D3: Positivo ↑ | E3: 3.9 | F3: 5 | G3: =IF(E3="","–",IF(D3="Negativo ↓",MIN(10,MAX(0,IFERROR(F3/E3*10,0))),MIN(10,MAX(0,IFERROR(E3/F3*10,0))))) -> 7.8 | H3: El índice MMCTI mide qué tan avanzada está la ciudad en su transformación inteligente. Una ciudad que no se mide no puede mejorar — este indicador es el termómetro global de la estrategia Smart City y permite priorizar inversiones en las dimensiones más rezagadas. | I3: https://cucuta.gov.co/cucuta-subio-0-5-puntos-en-el-indice-de-madurez-de-ciudades-y-territorios-inteligentes-2/ | J3: 2021
A4: 2 | B4: Datasets de datos abiertos publicados | C4: Número de conjuntos de datos públicos disponibles en el Portal Nacional de Datos Abiertos (datos.gov.co) relacionados con Cúcuta. (0=ningún dato / mayor número=mayor transparencia) | D4: Positivo ↑ | E4: 91 | F4: 200 | G4: =IF(E4="","–",IF(D4="Negativo ↓",MIN(10,MAX(0,IFERROR(F4/E4*10,0))),MIN(10,MAX(0,IFERROR(E4/F4*10,0))))) -> 4.55 | H4: Los datos abiertos son el combustible de la innovación urbana. Sin datos públicos, los ciudadanos no pueden auditar al gobierno, los empresarios no pueden crear servicios digitales, y los investigadores no pueden resolver problemas urbanos. Una Smart City es una ciudad que abre sus datos. | I4: https://www.datos.gov.co | J4: 2025
A5: 3 | B5: Cámaras de videovigilancia operativas | C5: Número de cámaras CCTV del sistema de vigilancia urbana activas. Cúcuta cuenta con 311 cámaras fijas y PTZ distribuidas en 322 puntos en las 10 comunas. El 96% están en funcionamiento. | D5: Positivo ↑ | E5: 311 | F5: 500 | G5: =IF(E5="","–",IF(D5="Negativo ↓",MIN(10,MAX(0,IFERROR(F5/E5*10,0))),MIN(10,MAX(0,IFERROR(E5/F5*10,0))))) -> 6.22 | H5: La videovigilancia inteligente es la columna vertebral de la seguridad urbana. Permite la captura de delincuentes, el monitoreo en tiempo real y la reducción de la criminalidad. Una Smart City amplía y moderniza su red de cámaras con IA para anticipar, no solo reaccionar. | I5: https://cucuta.gov.co/camaras-de-seguridad-han-ayudado-a-reducirlos-delitos-en-cucuta-en-el-2022/ | J5: 2022
A6: 4 | B6: Inversión en tecnología y seguridad urbana (millones COP) | C6: Inversión aprobada para modernización del sistema de videovigilancia urbana con inteligencia artificial — 2.000+ cámaras, centro de monitoreo y observatorio de seguridad. | D6: Positivo ↑ | E6: 32000 | F6: 50000 | G6: =IF(E6="","–",IF(D6="Negativo ↓",MIN(10,MAX(0,IFERROR(F6/E6*10,0))),MIN(10,MAX(0,IFERROR(E6/F6*10,0))))) -> 6.4 | H6: La inversión en tecnología de seguridad refleja la voluntad política de transformar la ciudad. Una Smart City no solo habla de innovación — la financia. Este indicador mide si la ciudad está respaldando su estrategia inteligente con recursos reales. | I6: https://metropolitano.com.co/cucuta-instalara-2-000-camaras-con-inteligencia-artificial/ | J6: 2025
A7: 5 | B7: Índice de Gobierno Digital local (0-100) | C7: Puntaje (0-100) del Índice de Gobierno Digital del MinTIC, que mide la implementación de la Política de Gobierno Digital en servicios ciudadanos, innovación pública, cultura digital, arquitectura empresarial y seguridad. | D7: Positivo ↑ | E7: 76.27 | F7: 100 | G7: =IF(E7="","–",IF(D7="Negativo ↓",MIN(10,MAX(0,IFERROR(F7/E7*10,0))),MIN(10,MAX(0,IFERROR(E7/F7*10,0))))) -> 7.627 | H7: El IGD mide si el gobierno local está realmente digitalizando sus servicios o solo simulando hacerlo. Un puntaje alto significa que los ciudadanos pueden hacer trámites en línea, que los datos fluyen entre entidades y que el gobierno toma decisiones basadas en datos — todo esencial para una Smart City. | I7: https://www.datos.gov.co/Ciencia-Tecnolog-a-e-Innovaci-n/-ndice-de-Gobierno-Digital-Hist-rico/rtai-k9uh | J7: 2021
A8: 6 | B8: Presupuesto municipal per cápita (USD) | C8: Presupuesto total aprobado de la Alcaldía de Cúcuta dividido entre el total de habitantes. Fórmula: Presupuesto 2024 (~$2.09B COP / TRM $4.200 = ~$497M USD) / 800.000 hab = ~$621 USD/hab. | D8: Positivo ↑ | E8: 621 | F8: 1000 | G8: =IF(E8="","–",IF(D8="Negativo ↓",MIN(10,MAX(0,IFERROR(F8/E8*10,0))),MIN(10,MAX(0,IFERROR(E8/F8*10,0))))) -> 6.21 | H8: El presupuesto per cápita determina cuántos recursos tiene el gobierno para invertir en cada ciudadano. Una ciudad con bajo presupuesto por habitante tiene limitaciones estructurales para financiar infraestructura inteligente, servicios digitales y programas sociales. Es el indicador de la capacidad fiscal real. | I8: https://www.alertasantanderes.com/norte-santander/concejo-de-cucuta-aprobo-presupuesto-de-23-billones-para-la-vigencia-2025 | J8: 2024
A9: 7 | B9: Ejecución presupuestal (%) | C9: Porcentaje del presupuesto definitivo efectivamente pagado en la vigencia. Fórmula: Pagos ($1.503.648.832.695) / Presupuesto definitivo ($1.898.321.345.031) × 100 = 85.66%. Dato: enero-noviembre 2023. | D9: Positivo ↑ | E9: 85.66 | F9: 95 | G9: =IF(E9="","–",IF(D9="Negativo ↓",MIN(10,MAX(0,IFERROR(F9/E9*10,0))),MIN(10,MAX(0,IFERROR(E9/F9*10,0))))) -> 9.0168421 | H9: La ejecución presupuestal mide si la ciudad cumple lo que promete. Un gobierno que planea pero no ejecuta no puede transformarse en Smart City. Este indicador revela la capacidad operativa real de la administración para convertir recursos aprobados en obras y servicios concretos para los ciudadanos. | I9: https://drive.google.com/file/d/1qwMzId6nlJ2M4xQ9W9q9Vtd2sz6palrP/view | J9: 2023
A10: PUNTAJE PROMEDIO DE LA DIMENSIÓN | G10: =IFERROR(AVERAGEIF(G3:G9,"<>–"),0) -> 6.8319774

Sheet Medio Ambiente
A1: INDICADORES DE MEDIO AMBIENTE
A2: No. | B2: Indicador | C2: Descripción / Unidad de medida | D2: Tipo | E2: Valor Real | F2: Ref. Óptima | G2: Puntaje (0-10) | H2: Justificación del indicador para Smart City | I2: Link de fuente | J2: Año del dato
A3: 1 | B3: Arbolado urbano con problemas fitosanitarios (%) | C3: Porcentaje de árboles del bosque urbano con condiciones fitosanitarias deficientes (pudrición, comején, malas podas, cáncer vegetal). NEGATIVO: menor valor = mejor. Acción de mejora: durante el cuatrienio 2020-2023 se sembraron 114.000 especies nativas. Fuente: Alcaldía de San José de Cúcuta — Plan de Desarrollo Municipal (PDM) 2024-2027. | D3: Negativo ↓ | E3: 60 | F3: 20 | G3: =IF(E3="","–",IF(D3="Negativo ↓",MIN(10,MAX(0,IFERROR(F3/E3*10,0))),MIN(10,MAX(0,IFERROR(E3/F3*10,0))))) -> 3.3333333 | H3: El estado fitosanitario del arbolado urbano refleja la calidad del ecosistema verde de la ciudad. Una ciudad inteligente monitorea y gestiona su bosque urbano con tecnología SIG (Sistema de Información Geográfica) y sensores IoT, como ya lo hace Cúcuta con ArcGIS. Sin árboles sanos no hay regulación del clima urbano, captura de CO₂ ni calidad de vida. | I3: https://cucuta.gov.co/wp-content/uploads/2024/06/Plan-de-Desarrollo-Municipal-Cucuta-perseverante-segura-y-productiva-2024-2027.pdf | J3: 2024
A4: 2 | B4: Índice de Calidad del Aire — AQI (promedio anual) | C4: AQI ( Índice de Calidad del Aire): escala 0-500 donde 0-50=Bueno / 51-100=Moderado / 101-150=Pobre para grupos sensibles. Promedio anual 2025 basado en mediciones continuas. NEGATIVO: menor valor = mejor. | D4: Negativo ↓ | E4: 50 | F4: 30 | G4: =IF(E4="","–",IF(D4="Negativo ↓",MIN(10,MAX(0,IFERROR(F4/E4*10,0))),MIN(10,MAX(0,IFERROR(E4/F4*10,0))))) -> 6 | H4: El AQI (Índice de Calidad del Aire) mide en tiempo real la salud del aire que respiran los ciudadanos. Una Smart City integra sensores de calidad del aire en su plataforma de datos urbanos para tomar decisiones sobre movilidad, industria y salud pública. Cúcuta tiene alta vulnerabilidad por su geografía de cuenca cerrada que acumula contaminantes. | I4: https://www.aqi.in/es/world-most-polluted-cities | J4: 2025
A5: 3 | B5: Tratamiento de aguas residuales (%) | C5: Porcentaje de aguas residuales domésticas e industriales que reciben tratamiento antes de ser vertidas. Cúcuta actualmente no cuenta con PTAR (Planta de Tratamiento de Aguas Residuales) en operación. Sin embargo, se encuentran en estructuración 3 plantas cuya licitación supera los USD 2.000 millones. NEGATIVO: menor valor = peor. | D5: Positivo ↑ | E5: 0 | F5: 80 | G5: =IF(E5="","–",IF(D5="Negativo ↓",MIN(10,MAX(0,IFERROR(F5/E5*10,0))),MIN(10,MAX(0,IFERROR(E5/F5*10,0))))) -> 0 | H5: El tratamiento de aguas residuales es un indicador crítico de sostenibilidad urbana. Una Smart City gestiona su ciclo del agua completo: captación, distribución, uso y tratamiento. La ausencia de PTAR en Cúcuta representa un riesgo ambiental severo para el río Pamplonita. La implementación de plantas inteligentes con sensores en tiempo real es parte esencial de la agenda de ciudad inteligente. | I5: https://dertransporte.uexternado.edu.co/colombia-licitara-proyectos-de-infraestructura-hidrica-por-us2-000-millones-en-cucuta-y-sta-marta/ | J5: 2024
A6: 4 | B6: Gestión de residuos sólidos — % aprovechado | C6: Porcentaje de residuos sólidos que son efectivamente reciclados, compostados o aprovechados sobre el total generado. SSPD (Superintendencia de Servicios Públicos Domiciliarios) — Informe AAA (Acueducto, Alcantarillado y Aseo) 2023. POSITIVO: mayor valor = mejor. | D6: Positivo ↑ | E6: 3 | F6: 25 | G6: =IF(E6="","–",IF(D6="Negativo ↓",MIN(10,MAX(0,IFERROR(F6/E6*10,0))),MIN(10,MAX(0,IFERROR(E6/F6*10,0))))) -> 1.2 | H6: El aprovechamiento de residuos es el corazón de la economía circular urbana. Una Smart City implementa rutas de recolección inteligentes con GPS (Sistema de Posicionamiento Global), puntos de reciclaje georreferenciados y plataformas de trazabilidad de residuos. El 0% de Cúcuta contrasta con ciudades líderes que superan el 30%, lo que representa una enorme oportunidad de transformación. | I6: https://www.laopinion.co/cucuta/entre-residuos-y-esperanza-los-recicladores-que-sostienen-la-economia-circular-en-cucuta | J6: 2023
A7: 5 | B7: PM2.5 — material particulado fino (µg/m³ promedio anual) | C7: PM2.5 (Material Particulado con diámetro ≤2,5 micrómetros): partículas finas suspendidas en el aire, las más dañinas para la salud. Medido por Corponor (Corporación Autónoma Regional de la Frontera Nororiental) en 4 estaciones fijas: El Salado, Comuneros, El Centro y Atalaya. Meta OMS (Organización Mundial de la Salud): ≤5 µg/m³. NEGATIVO: menor valor = mejor. | D7: Negativo ↓ | E7: 10 | F7: 5 | G7: =IF(E7="","–",IF(D7="Negativo ↓",MIN(10,MAX(0,IFERROR(F7/E7*10,0))),MIN(10,MAX(0,IFERROR(E7/F7*10,0))))) -> 5 | H7: El PM2.5 es el contaminante atmosférico con mayor impacto en la salud pública — penetra el sistema respiratorio y cardiovascular. Una Smart City monitorea el PM2.5 en tiempo real con redes de sensores y publica los datos abiertos para que ciudadanos y autoridades tomen decisiones informadas. Cúcuta tiene 4 estaciones de la red SISAIRE (Sistema de Información sobre Calidad del Aire) operativas. | I7: https://corponor.gov.co/web/index.php/boletin-ambiental/calidad-del-aire/ | J7: 2024
A8: 6 | B8: Residuos sólidos per cápita (kg/hab/año) | C8: Kilogramos de residuos sólidos generados por habitante al año. Fórmula: 266.492,75 toneladas dispuestas en 2023 (Relleno Sanitario El Guayabal, fuente SUI — Sistema Único de Información) × 1.000 / 800.000 hab = 333 kg/hab/año. NEGATIVO: menor valor = mejor. | D8: Negativo ↓ | E8: 333 | F8: 200 | G8: =IF(E8="","–",IF(D8="Negativo ↓",MIN(10,MAX(0,IFERROR(F8/E8*10,0))),MIN(10,MAX(0,IFERROR(E8/F8*10,0))))) -> 6.006006 | H8: La generación per cápita de residuos mide la presión ambiental que ejerce cada ciudadano sobre el territorio. Una Smart City combina educación ciudadana, incentivos digitales y rutas de recolección optimizadas con IA (Inteligencia Artificial) para reducir este indicador. 333 kg/hab/año supera el promedio latinoamericano de ciudades sostenibles (200-250 kg), indicando un margen de mejora significativo. | I8: https://cucuta.gov.co/wp-content/uploads/2024/06/Plan-de-Desarrollo-Municipal-Cucuta-perseverante-segura-y-productiva-2024-2027.pdf | J8: 2023
A9: 7 | B9: Estaciones de monitoreo ambiental activas | C9: Número de estaciones fijas de monitoreo de calidad del aire en operación continua. Corponor (Corporación Autónoma Regional de la Frontera Nororiental) opera 4 estaciones fijas urbanas en Cúcuta: El Salado, Comuneros, El Centro y Atalaya. Reportan a la red SISAIRE (Sistema de Información sobre Calidad del Aire). POSITIVO: mayor número = mejor capacidad de monitoreo. | D9: Positivo ↑ | E9: 4 | F9: 8 | G9: =IF(E9="","–",IF(D9="Negativo ↓",MIN(10,MAX(0,IFERROR(F9/E9*10,0))),MIN(10,MAX(0,IFERROR(E9/F9*10,0))))) -> 5 | H9: Las estaciones de monitoreo son los ojos ambientales de la ciudad. Sin datos en tiempo real no hay gestión ambiental inteligente. Una Smart City integra estas estaciones en un dashboard (panel de control) de ciudad en tiempo real, permite alertas automáticas a ciudadanos y conecta los datos con decisiones de movilidad y salud pública. 4 estaciones es un inicio, pero insuficiente para una ciudad de 800.000 habitantes. | I9: https://corponor.gov.co/web/index.php/boletin-ambiental/calidad-del-aire/ | J9: 2024
A10: 8 | B10: Energía solar fotovoltaica instalada (MW) | C10: Capacidad instalada total de generación solar fotovoltaica en el municipio en megavatios (MW). Proyectos confirmados: Termotasajero II Solar (5.2 MW, 9.600 paneles, 4 hectáreas, inaugurado enero 2023) + Sistema fotovoltaico Unicentro EPM (0.777 MW, 1.426 paneles, diciembre 2023) = 5.977 MW. Meta PDM (Plan de Desarrollo Municipal) 2024-2027: 20 MW. POSITIVO: mayor valor = mejor. | D10: Positivo ↑ | E10: 5.98 | F10: 20 | G10: =IF(E10="","–",IF(D10="Negativo ↓",MIN(10,MAX(0,IFERROR(F10/E10*10,0))),MIN(10,MAX(0,IFERROR(E10/F10*10,0))))) -> 2.99 | H10: La capacidad solar instalada mide el avance real de la transición energética local. Una Smart City diversifica su matriz con energías renovables, reduce su huella de carbono y garantiza resiliencia energética. Cúcuta tiene alta irradiación solar durante todo el año, lo que la convierte en territorio ideal para el desarrollo fotovoltaico. El proyecto PSFV (Parque Solar Fotovoltaico) Tonchalá de 19.9 MW está en registro UPME para 2026. | I10: https://www.semana.com/nacion/cucuta/articulo/mas-de-4000-hogares-de-norte-de-santander-se-beneficiaran-con-energias-limpias-gracias-a-proyecto-de-energia-solar/202342/ | https://www.pv-magazine-latam.com/2023/12/19/la-colombiana-epm-instala-su-mayor-sistema-fotovoltaico-en-un-centro-comercial/ | J10: 2023
A11: 9 | B11: Cobertura de acueducto urbano (%) | C11: Porcentaje de hogares urbanos con acceso a red de acueducto y agua potable. Dato: Norte de Santander cobertura urbana 94% en 2023 (Gobernación NdS — Secretaría de Agua Potable y Saneamiento Básico). Nota: dato departamental — Cúcuta como capital concentra la mayor infraestructura urbana y se asume cobertura igual o superior al promedio departamental. ODS (Objetivo de Desarrollo Sostenible) 6: Agua limpia y saneamiento. | D11: Positivo ↑ | E11: 94 | F11: 99 | G11: =IF(E11="","–",IF(D11="Negativo ↓",MIN(10,MAX(0,IFERROR(F11/E11*10,0))),MIN(10,MAX(0,IFERROR(E11/F11*10,0))))) -> 9.4949495 | H11: La cobertura de acueducto mide el acceso equitativo al agua potable — un derecho humano fundamental y prerequisito de cualquier ciudad inteligente. Sin acceso universal al agua no puede haber Smart City. Este indicador también refleja la capacidad de la empresa de servicios públicos EIS (Empresa Industrial y de Servicios) para expandir infraestructura, y es directamente comparable con ciudades fronterizas de LATAM. | I11: https://administrador.nortedesantander.gov.co/wp-content/uploads/2023/11/BALANCE-DE-GESTION-2020-2023-SECRETARIA-DE-AGUA-POTABLE-Y-SANEAMIENTO-BASICO.pdf | J11: 2023
A12: 10 | B12: Cobertura de alcantarillado urbano (%) | C12: Porcentaje de hogares urbanos conectados a red de alcantarillado. Dato: Norte de Santander cobertura urbana 99,2% en 2023 (Gobernación NdS — Secretaría de Agua Potable y Saneamiento Básico). Nota: dato departamental — Cúcuta como capital concentra la mayor infraestructura urbana. Cobertura rural alcantarillado: 17,60%. ODS (Objetivo de Desarrollo Sostenible) 6: Agua limpia y saneamiento. | D12: Positivo ↑ | E12: 99.2 | F12: 100 | G12: =IF(E12="","–",IF(D12="Negativo ↓",MIN(10,MAX(0,IFERROR(F12/E12*10,0))),MIN(10,MAX(0,IFERROR(E12/F12*10,0))))) -> 9.92 | H12: La cobertura de alcantarillado mide la gestión del agua residual post-consumo. Una Smart City cierra el ciclo del agua: captación (acueducto), uso y retorno (alcantarillado + tratamiento). El 99.2% urbano es un resultado destacado, pero contrasta con el 0% de tratamiento de esas aguas antes de ser vertidas al río Pamplonita — lo que evidencia que tener red de alcantarillado no equivale a gestión ambiental completa. | I12: https://administrador.nortedesantander.gov.co/wp-content/uploads/2023/11/BALANCE-DE-GESTION-2020-2023-SECRETARIA-DE-AGUA-POTABLE-Y-SANEAMIENTO-BASICO.pdf | J12: 2023
A13: 11 | B13: Hectáreas de áreas estratégicas para conservación hídrica | C13: Número de hectáreas adquiridas por la Alcaldía de Cúcuta para protección de cuencas hidrográficas y fuentes de agua que abastecen los acueductos municipales. PDM (Plan de Desarrollo Municipal) 2024-2027: meta de adquirir 1.600 hectáreas adicionales para llegar a 2.500 ha protegidas. Dato exclusivo de predios en Cúcuta (excluye municipios vecinos de la misma tabla). POSITIVO: mayor valor = mejor. | D13: Positivo ↑ | E13: 1575 | F13: 2500 | G13: =IF(E13="","–",IF(D13="Negativo ↓",MIN(10,MAX(0,IFERROR(F13/E13*10,0))),MIN(10,MAX(0,IFERROR(E13/F13*10,0))))) -> 6.3 | H13: La conservación de áreas estratégicas es la política ambiental más inteligente a largo plazo: sin proteger las cuencas que abastecen los acueductos, ninguna tecnología puede garantizar el agua futura de la ciudad. Una Smart City integra la gestión de estas áreas con SIG (Sistemas de Información Geográfica), monitoreo satelital y sensores de caudal para anticipar riesgos hídricos y garantizar el suministro a generaciones futuras. | I13: https://cucuta.gov.co/wp-content/uploads/2024/06/Plan-de-Desarrollo-Municipal-Cucuta-perseverante-segura-y-productiva-2024-2027.pdf | https://www.semana.com/nacion/cucuta/articulo/las-acciones-que-se-utilizan-en-cucuta-para-reducir-la-contaminacion-y-preservar-el-medio-ambiente/202316/ | J13: 2024
A14: PUNTAJE PROMEDIO DE LA DIMENSIÓN | G14: =IFERROR(AVERAGEIF(G3:G13,"<>–"),0) -> 5.0222081

Sheet Frontera
A1: INDICADORES DE FRONTERA
A2: Modelo de Ciudad Inteligente – Cúcuta, Norte de Santander | ↑ Positivo: mayor = mejor | ↓ Negativo: menor = mejor
A3: No. | B3: Indicador | C3: Descripción / Unidad de medida | D3: Tipo | E3: Valor Real | F3: Ref. Óptima | G3: Puntaje (0-10) | H3: Justificación del indicador para Smart City | I3: Link de fuente | J3: Año del dato
A4: 1 | B4: Comercio binacional total por aduana de la ciudad (millones USD) | C4: Millones de USD — Valor total del comercio bilateral Colombia-Venezuela que pasa por la aduana de Cúcuta. Cúcuta concentra el 51% del comercio binacional total según informe CCC (Cámara de Comercio de Cúcuta) / DANE / Cavecol (Cámara de Integración Económica Venezolana-Colombiana). Comercio total bilateral primer semestre 2025: USD $560,7M FOB (Free On Board). Cálculo: $560.7M × 51% = ~$286M USD. POSITIVO: mayor valor = mejor. | D4: Positivo ↑ | E4: 286 | F4: 800 | G4: =IF(E4="","–",IF(D4="Negativo ↓",MIN(10,MAX(0,IFERROR(F4/E4*10,0))),MIN(10,MAX(0,IFERROR(E4/F4*10,0))))) -> 3.575 | H4: El volumen de comercio binacional es el indicador más directo de la función económica de Cúcuta como ciudad fronteriza. Una Smart City gestiona el comercio fronterizo con sistemas digitales de trazabilidad, ventanillas únicas aduaneras y plataformas de comercio electrónico transfronterizo. La reapertura de la frontera en 2022 tras 7 años de cierre representó un punto de inflexión histórico — Cúcuta pasó de ser la segunda aduana (29% en 2024) a la primera (51% en 2025), consolidándose como el principal hub del comercio colombo-venezolano. | I4: https://cccucuta.org.co/vnoticias/221/comercio-binacional-alcanzo-us5607-millones-en-el-primer-semestre-de-2025 | J4: 2025
A5: 2 | B5: Flujo migratorio fronterizo (cruces/año) | C5: Número total de cruces anuales registrados en los 5 PCM (Puestos de Control Migratorio) de Cúcuta. Incluye flujos bidireccionales de residentes y no residentes, colombianos y extranjeros, en tránsito pendular diario (compras, trabajo, salud, familia). Cálculo: ~60.000 cruces/día × 365 días = 21.900.000/año. La Regional Oriente de Migración Colombia concentra el 86.3% de todos los cruces fronterizos colombo-venezolanos del país. POSITIVO: mayor valor = mayor dinamismo fronterizo. | D5: Positivo ↑ | E5: 21900000 | F5: 18000000 | G5: =IF(E5="","–",IF(D5="Negativo ↓",MIN(10,MAX(0,IFERROR(F5/E5*10,0))),MIN(10,MAX(0,IFERROR(E5/F5*10,0))))) -> 10 | H5: El flujo migratorio fronterizo mide la intensidad de las relaciones humanas y económicas entre ambos países. Una Smart City gestiona este flujo con tecnología biométrica, sistemas de identificación digital y plataformas de atención al migrante en línea. Cúcuta es el principal punto de cruce terrestre de Venezuela hacia Suramérica — gestionar este flujo inteligentemente es esencial para la cohesión social, la seguridad urbana y la economía fronteriza. | I5: https://www.eltiempo.com/politica/gobierno/migracion-colombia-da-parte-de-tranquilidad-por-el-flujo-migratorio-en-la-frontera-con-venezuela-hacemos-monitoreo-tres-veces-al-dia-3522180 | J5: 2026
A6: 3 | B6: Migrantes con vocación de permanencia en la ciudad | C6: Número de personas extranjeras con intención declarada de establecerse permanentemente en la ciudad de Cúcuta. El 64.92% de los 328.820 venezolanos en Norte de Santander se concentran en Cúcuta = 213.487 personas. POSITIVO: mayor valor = mayor dinamismo migratorio, pero también mayor presión sobre servicios urbanos. | D6: Positivo ↑ | E6: 213487 | F6: 150000 | G6: =IF(E6="","–",IF(D6="Negativo ↓",MIN(10,MAX(0,IFERROR(F6/E6*10,0))),MIN(10,MAX(0,IFERROR(E6/F6*10,0))))) -> 10 | H6: Los migrantes con vocación de permanencia representan la población que la ciudad debe integrar económica y socialmente a largo plazo. Una Smart City diseña servicios públicos digitales accesibles para todos los residentes independientemente de su estatus migratorio — aplicaciones de salud en línea, registro escolar digital y geolocalización de puntos de atención. Cúcuta alberga la mayor concentración de migrantes venezolanos del país después de Bogotá y Medellín. | I6: https://www.r4v.info/sites/g/files/tmzbdl2426/files/2024-11/Factsheet%20R&M%20NdeS%202024%20(ene-sept)_0.pdf | J6: 2024
A7: 4 | B7: Exportaciones por aduana de la ciudad (miles USD/FOB) | C7: Miles de USD FOB (Free On Board) exportados a través de la aduana de Cúcuta enero-diciembre 2025. Variación: +22.7% frente a 2024 ($327.862 miles). Principal destino: Venezuela (19.4%), Brasil (11.4%) y Bélgica (8.1%). Medio de transporte: marítimo (79.9%), terrestre (19.7%), aéreo (0.4%). Fuente: DANE / LEGISCOMEX — Observatorio Económico CCC (Cámara de Comercio de Cúcuta). POSITIVO: mayor valor = mejor. | D7: Positivo ↑ | E7: 402252 | F7: 600000 | G7: =IF(E7="","–",IF(D7="Negativo ↓",MIN(10,MAX(0,IFERROR(F7/E7*10,0))),MIN(10,MAX(0,IFERROR(E7/F7*10,0))))) -> 6.7042 | H7: Las exportaciones por aduana Cúcuta miden la capacidad de la ciudad de colocar productos en mercados internacionales. Una Smart City desarrolla plataformas de inteligencia comercial, ventanillas únicas de comercio exterior digitales y programas de internacionalización empresarial. El crecimiento del 22.7% en 2025 refleja la consolidación de Cúcuta como hub exportador de la frontera colombo-venezolana y su diversificación hacia mercados de Europa y Asia. | I7: https://datacucuta.com/indicadores-regionales/comercio-exterior/exportaciones/exportaciones-diciembre-2025/ | J7: 2025
A8: 5 | B8: Importaciones por aduana de la ciudad (miles USD/CIF) | C8: Miles de USD CIF (Cost, Insurance and Freight) importados a través de la aduana de Cúcuta enero-diciembre 2025. Variación: -37% frente a 2024 ($123.813 miles). Principales países de origen: Estados Unidos (42.4%), China (33.2%) y Venezuela (3.7%). Principales productos: combustibles minerales (21.1%), materias plásticas (10.8%) y cereales (8.1%). Fuente: DANE / LEGISCOMEX — Observatorio Económico CCC. POSITIVO: mayor valor = mayor dinamismo comercial entrante. | D8: Positivo ↑ | E8: 77950 | F8: 150000 | G8: =IF(E8="","–",IF(D8="Negativo ↓",MIN(10,MAX(0,IFERROR(F8/E8*10,0))),MIN(10,MAX(0,IFERROR(E8/F8*10,0))))) -> 5.1966667 | H8: Las importaciones miden el flujo de bienes y servicios que entran a la ciudad desde el exterior. Una Smart City optimiza sus procesos aduaneros con plataformas digitales que reducen tiempos de nacionalización y facilita el comercio a las MIPYME (Micro, Pequeñas y Medianas Empresas) locales. La caída del 37% refleja la volatilidad comercial de la frontera colombo-venezolana. | I8: https://datacucuta.com/indicadores-regionales/comercio-exterior/importaciones/importaciones-diciembre-2025/ | J8: 2025
A9: 6 | B9: Pasos fronterizos internacionales activos en la ciudad y su área metropolitana | C9: Número de puentes internacionales activos que conectan a Cúcuta y su área metropolitana con Venezuela. Los 3 puentes son: (1) Francisco de Paula Santander — conecta Cúcuta con Ureña, principal paso de importaciones; (2) Atanasio Girardot (Tienditas) — 6 carriles, 280 metros, exclusivo vehículos de carga, el más moderno de LATAM; (3) Simón Bolívar — conecta Villa del Rosario/Cúcuta A.M. con San Antonio, principal paso de exportaciones. La Cámara Colombo Venezolana los referencia oficialmente como los puentes de San José de Cúcuta. POSITIVO: mayor valor = mejor. | D9: Positivo ↑ | E9: 3 | F9: 3 | G9: =IF(E9="","–",IF(D9="Negativo ↓",MIN(10,MAX(0,IFERROR(F9/E9*10,0))),MIN(10,MAX(0,IFERROR(E9/F9*10,0))))) -> 10 | H9: Los puentes internacionales son la infraestructura física que hace posible la Smart City fronteriza. Sin conectividad física no hay flujo comercial, migratorio ni cultural. Una Smart City moderniza sus pasos fronterizos con tecnología de reconocimiento facial, sistemas de aforo inteligente, CEBAF (Centro Binacional de Atención en Frontera) y CENAF (Centro Nacional de Fronteras) digitalizados. Los 3 puentes activos representan el máximo histórico de apertura fronteriza entre Colombia y Venezuela. | I9: https://comvenezuela.com/camara-colombo-venezolana-destaca-incremento-del-intercambio-comercial-bilateral-facilitado-por-la-reapertura-de-puentes-internacionales/ | J9: 2024
A10: 7 | B10: Vehículos de carga por pasos fronterizos (promedio mensual) | C10: Número promedio mensual de vehículos de carga que transitan por los 3 puentes internacionales de Cúcuta y su área metropolitana. Dato: promedio enero-abril 2024 = 1.108 vehículos/mes, representando un incremento del 55% frente al mismo período de 2023 (717 vehículos/mes). Fuente: MinCIT (Ministerio de Comercio, Industria y Turismo) / Cámara Colombo Venezolana. POSITIVO: mayor valor = mejor. | D10: Positivo ↑ | E10: 1108 | F10: 2000 | G10: =IF(E10="","–",IF(D10="Negativo ↓",MIN(10,MAX(0,IFERROR(F10/E10*10,0))),MIN(10,MAX(0,IFERROR(E10/F10*10,0))))) -> 5.54 | H10: El flujo de vehículos de carga mide la intensidad del comercio físico a través de la frontera. Una Smart City implementa sistemas de gestión inteligente del tráfico de carga, plataformas de pre-declaración aduanera digital y carriles expresos para vehículos con documentación completa. El +55% de crecimiento en 2024 refleja la reactivación del corredor logístico Cúcuta-Táchira como el más importante de la frontera colombo-venezolana. | I10: https://comvenezuela.com/camara-colombo-venezolana-destaca-incremento-del-intercambio-comercial-bilateral-facilitado-por-la-reapertura-de-puentes-internacionales/ | J10: 2024
A11: 8 | B11: Puestos de Control Migratorio activos en la ciudad | C11: Número de PCM (Puestos de Control Migratorio) de Migración Colombia activos específicamente en Cúcuta ciudad: (1) PCMT La Unidad — Puente Atanasio Girardot; (2) PCMA Camilo Daza — Aeropuerto Internacional. Los otros 3 PCM de Norte de Santander (Simón Bolívar/Villa del Rosario, Francisco de Paula Santander, Puerto Santander) no están dentro del perímetro urbano de Cúcuta. POSITIVO: mayor valor = mejor control y servicio migratorio. | D11: Positivo ↑ | E11: 2 | F11: 4 | G11: =IF(E11="","–",IF(D11="Negativo ↓",MIN(10,MAX(0,IFERROR(F11/E11*10,0))),MIN(10,MAX(0,IFERROR(E11/F11*10,0))))) -> 5 | H11: Los PCM son los puntos de control y servicio migratorio donde se registran formalmente los flujos de personas. Una Smart City fronteriza integra sus PCM en un sistema biométrico unificado con reconocimiento facial, interoperabilidad con bases de datos de seguridad de ambos países y expedición digital de documentos. Con 2 PCM propios, Cúcuta tiene capacidad de control formal en su territorio. | I11: https://www.migracioncolombia.gov.co/especiales-digitales/flujos-migratorios-pendulares-y-regulares-en-la-frontera | J11: 2026
A12: 9 | B12: Extranjeros del país vecino no residentes que ingresan a la ciudad (año) | C12: Número de ciudadanos venezolanos no residentes que ingresaron formalmente a Cúcuta en 2025 con registro migratorio. Mide exclusivamente el flujo Venezuela→Cúcuta de personas que visitan la ciudad sin residir permanentemente — comerciantes, visitantes y personas en tránsito con registro formal. Fuente: Migración Colombia — dataset "Extranjeros No Residentes" en datos.gov.co. POSITIVO: mayor valor = mayor dinamismo fronterizo formal. | D12: Positivo ↑ | E12: 21104000 | F12: 40000000 | G12: =IF(E12="","–",IF(D12="Negativo ↓",MIN(10,MAX(0,IFERROR(F12/E12*10,0))),MIN(10,MAX(0,IFERROR(E12/F12*10,0))))) -> 5.276 | H12: Los venezolanos no residentes que visitan Cúcuta formalmente representan el comercio y los lazos familiares activos entre ambos países. Una Smart City facilita este flujo con trámites digitales, visas electrónicas y puntos de atención biométrica que reducen tiempos de espera. Este indicador mide específicamente la dirección Venezuela→Cúcuta del intercambio humano formal — esencial para entender la dimensión real de la frontera como espacio de integración binacional. | I12: https://www.datos.gov.co/Estad-sticas-Nacionales/Extranjeros-No-Residentes/s7st-tyxk | J12: 2025
A13: 10 | B13: Balanza comercial binacional por aduana de la ciudad (miles USD) | C13: Miles de USD — Diferencia entre exportaciones e importaciones por la aduana de Cúcuta. Fórmula: Exportaciones (402.252 miles USD/FOB 2025) − Importaciones (77.950 miles USD/CIF 2025) = 324.302 miles USD. Superávit comercial a favor de Cúcuta. Fuente: DANE / LEGISCOMEX — Observatorio Económico CCC (Cámara de Comercio de Cúcuta). POSITIVO: mayor superávit = mejor posición comercial. | D13: Positivo ↑ | E13: 324302 | F13: 400000 | G13: =IF(E13="","–",IF(D13="Negativo ↓",MIN(10,MAX(0,IFERROR(F13/E13*10,0))),MIN(10,MAX(0,IFERROR(E13/F13*10,0))))) -> 8.10755 | H13: La balanza comercial mide la posición neta de la ciudad en el intercambio con Venezuela — si exporta más de lo que importa, genera riqueza para la economía local. Una Smart City fronteriza monitorea su balanza en tiempo real con dashboards (paneles de control) conectados a los sistemas de la DIAN (Dirección de Impuestos y Aduanas Nacionales) y la CCC, permitiendo decisiones de política comercial basadas en datos. El superávit de $324M refleja la competitividad exportadora de Cúcuta frente al mercado venezolano. | I13: https://datacucuta.com/indicadores-regionales/comercio-exterior/exportaciones/exportaciones-diciembre-2025/ | https://datacucuta.com/indicadores-regionales/comercio-exterior/importaciones/importaciones-diciembre-2025/ | J13: 2025
A14: PUNTAJE PROMEDIO DE LA DIMENSIÓN | G14: =IFERROR(AVERAGEIF(G4:G13,"<>–"),0) -> 6.9399417

Sheet Resumen Puntajes
B1: RESUMEN DE PUNTAJES – ÍNDICE CIUDAD INTELIGENTE CÚCUTA
B2: Los puntajes se calculan automáticamente. Ingrese los Valores Reales en cada hoja de dimensión (celdas amarillas).
B4: Dimensión | C4: Puntaje (0-10) | D4: N° Indicadores | E4: Peso (%) | F4: Puntaje Ponderado
B5: Capital humano | C5: ='Capital Humano'!G16 -> 6.2249863 | D5: =Portada!C10 -> 13 | E5: =Portada!D10 -> 16 | F5: =(C5*E5/100) -> 0.9959978
B6: Cohesión Social | C6: ='Cohesión Social'!G16 -> 5.9630104 | D6: =Portada!C11 -> 13 | E6: =Portada!D11 -> 16 | F6: =(C6*E6/100) -> 0.95408167
B7: Economía | C7: =Economía!G9 -> 5.3375177 | D7: =Portada!C12 -> 6 | E7: =Portada!D12 -> 16 | F7: =(C7*E7/100) -> 0.85400283
B8: Gobernanza | C8: =Gobernanza!G10 -> 6.8319774 | D8: =Portada!C13 -> 7 | E8: =Portada!D13 -> 16 | F8: =(C8*E8/100) -> 1.0931164
B9: Medio Ambiente | C9: ='Medio Ambiente'!G14 -> 5.0222081 | D9: =Portada!C14 -> 11 | E9: =Portada!D14 -> 16 | F9: =(C9*E9/100) -> 0.80355329
B10: Frontera | C10: =Frontera!G14 -> 6.9399417 | D10: =Portada!C15 -> 10 | E10: =Portada!D15 -> 20 | F10: =(C10*E10/100) -> 1.3879883
B11: ÍNDICE COMPUESTO FINAL | D11: =SUM(D5:D10) -> 60 | E11: =SUM(E5:E10) -> 100 | F11: =SUM(F5:F10) -> 6.0887403
B13: Escala de interpretación del Índice Compuesto Final
B14: 0.0 – 3.9 | C14: Bajo | D14: Ciudad con desafíos críticos en múltiples dimensiones.
B15: 4.0 – 5.9 | C15: Medio-Bajo | D15: Avances parciales; requiere mejoras sustanciales.
